[2024-02-17 06:27:01] ERROR Internal Server Error: /api/v1/common/get_symptoms/
[2024-02-17 06:27:24] ERROR Internal Server Error: /api/v1/common/get_symptoms/
[2024-02-17 06:28:55] ERROR Internal Server Error: /api/v1/common/get_symptoms/
[2024-02-18 15:18:10] ERROR Internal Server Error: /api/v1/patient/create_appointment/
Traceback (most recent call last):
  File "/root/medical_services/medicalenv/lib/python3.10/site-packages/django/core/handlers/exception.py", line 55, in inner
    response = get_response(request)
  File "/root/medical_services/medicalenv/lib/python3.10/site-packages/django/core/handlers/base.py", line 197, in _get_response
    response = wrapped_callback(request, *callback_args, **callback_kwargs)
  File "/root/medical_services/medicalenv/lib/python3.10/site-packages/django/views/decorators/csrf.py", line 56, in wrapper_view
    return view_func(*args, **kwargs)
  File "/root/medical_services/medicalenv/lib/python3.10/site-packages/django/views/generic/base.py", line 104, in view
    return self.dispatch(request, *args, **kwargs)
  File "/root/medical_services/medicalenv/lib/python3.10/site-packages/rest_framework/views.py", line 511, in dispatch
    self.response = self.finalize_response(request, response, *args, **kwargs)
  File "/root/medical_services/medicalenv/lib/python3.10/site-packages/rest_framework/views.py", line 423, in finalize_response
    assert isinstance(response, HttpResponseBase), (
AssertionError: Expected a `Response`, `HttpResponse` or `HttpStreamingResponse` to be returned from the view, but received a `<class 'NoneType'>`
[2024-02-18 15:18:21] ERROR Internal Server Error: /api/v1/patient/create_appointment/
Traceback (most recent call last):
  File "/root/medical_services/medicalenv/lib/python3.10/site-packages/django/core/handlers/exception.py", line 55, in inner
    response = get_response(request)
  File "/root/medical_services/medicalenv/lib/python3.10/site-packages/django/core/handlers/base.py", line 197, in _get_response
    response = wrapped_callback(request, *callback_args, **callback_kwargs)
  File "/root/medical_services/medicalenv/lib/python3.10/site-packages/django/views/decorators/csrf.py", line 56, in wrapper_view
    return view_func(*args, **kwargs)
  File "/root/medical_services/medicalenv/lib/python3.10/site-packages/django/views/generic/base.py", line 104, in view
    return self.dispatch(request, *args, **kwargs)
  File "/root/medical_services/medicalenv/lib/python3.10/site-packages/rest_framework/views.py", line 511, in dispatch
    self.response = self.finalize_response(request, response, *args, **kwargs)
  File "/root/medical_services/medicalenv/lib/python3.10/site-packages/rest_framework/views.py", line 423, in finalize_response
    assert isinstance(response, HttpResponseBase), (
AssertionError: Expected a `Response`, `HttpResponse` or `HttpStreamingResponse` to be returned from the view, but received a `<class 'NoneType'>`
[2024-02-18 15:19:41] ERROR Internal Server Error: /api/v1/patient/create_appointment/
Traceback (most recent call last):
  File "/root/medical_services/medicalenv/lib/python3.10/site-packages/django/core/handlers/exception.py", line 55, in inner
    response = get_response(request)
  File "/root/medical_services/medicalenv/lib/python3.10/site-packages/django/core/handlers/base.py", line 197, in _get_response
    response = wrapped_callback(request, *callback_args, **callback_kwargs)
  File "/root/medical_services/medicalenv/lib/python3.10/site-packages/django/views/decorators/csrf.py", line 56, in wrapper_view
    return view_func(*args, **kwargs)
  File "/root/medical_services/medicalenv/lib/python3.10/site-packages/django/views/generic/base.py", line 104, in view
    return self.dispatch(request, *args, **kwargs)
  File "/root/medical_services/medicalenv/lib/python3.10/site-packages/rest_framework/views.py", line 511, in dispatch
    self.response = self.finalize_response(request, response, *args, **kwargs)
  File "/root/medical_services/medicalenv/lib/python3.10/site-packages/rest_framework/views.py", line 423, in finalize_response
    assert isinstance(response, HttpResponseBase), (
AssertionError: Expected a `Response`, `HttpResponse` or `HttpStreamingResponse` to be returned from the view, but received a `<class 'NoneType'>`
[2024-02-18 16:49:39] ERROR Internal Server Error: /api/v1/patient/create_appointment/
Traceback (most recent call last):
  File "/root/medical_services/medicalenv/lib/python3.10/site-packages/django/core/handlers/exception.py", line 55, in inner
    response = get_response(request)
  File "/root/medical_services/medicalenv/lib/python3.10/site-packages/django/core/handlers/base.py", line 197, in _get_response
    response = wrapped_callback(request, *callback_args, **callback_kwargs)
  File "/root/medical_services/medicalenv/lib/python3.10/site-packages/django/views/decorators/csrf.py", line 56, in wrapper_view
    return view_func(*args, **kwargs)
  File "/root/medical_services/medicalenv/lib/python3.10/site-packages/django/views/generic/base.py", line 104, in view
    return self.dispatch(request, *args, **kwargs)
  File "/root/medical_services/medicalenv/lib/python3.10/site-packages/rest_framework/views.py", line 511, in dispatch
    self.response = self.finalize_response(request, response, *args, **kwargs)
  File "/root/medical_services/medicalenv/lib/python3.10/site-packages/rest_framework/views.py", line 423, in finalize_response
    assert isinstance(response, HttpResponseBase), (
AssertionError: Expected a `Response`, `HttpResponse` or `HttpStreamingResponse` to be returned from the view, but received a `<class 'NoneType'>`
[2024-02-18 16:51:20] ERROR Internal Server Error: /api/v1/patient/create_appointment/
Traceback (most recent call last):
  File "/root/medical_services/medicalenv/lib/python3.10/site-packages/django/core/handlers/exception.py", line 55, in inner
    response = get_response(request)
  File "/root/medical_services/medicalenv/lib/python3.10/site-packages/django/core/handlers/base.py", line 197, in _get_response
    response = wrapped_callback(request, *callback_args, **callback_kwargs)
  File "/root/medical_services/medicalenv/lib/python3.10/site-packages/django/views/decorators/csrf.py", line 56, in wrapper_view
    return view_func(*args, **kwargs)
  File "/root/medical_services/medicalenv/lib/python3.10/site-packages/django/views/generic/base.py", line 104, in view
    return self.dispatch(request, *args, **kwargs)
  File "/root/medical_services/medicalenv/lib/python3.10/site-packages/rest_framework/views.py", line 511, in dispatch
    self.response = self.finalize_response(request, response, *args, **kwargs)
  File "/root/medical_services/medicalenv/lib/python3.10/site-packages/rest_framework/views.py", line 423, in finalize_response
    assert isinstance(response, HttpResponseBase), (
AssertionError: Expected a `Response`, `HttpResponse` or `HttpStreamingResponse` to be returned from the view, but received a `<class 'NoneType'>`
[2024-02-18 16:51:36] ERROR Internal Server Error: /api/v1/patient/create_appointment/
Traceback (most recent call last):
  File "/root/medical_services/medicalenv/lib/python3.10/site-packages/django/core/handlers/exception.py", line 55, in inner
    response = get_response(request)
  File "/root/medical_services/medicalenv/lib/python3.10/site-packages/django/core/handlers/base.py", line 197, in _get_response
    response = wrapped_callback(request, *callback_args, **callback_kwargs)
  File "/root/medical_services/medicalenv/lib/python3.10/site-packages/django/views/decorators/csrf.py", line 56, in wrapper_view
    return view_func(*args, **kwargs)
  File "/root/medical_services/medicalenv/lib/python3.10/site-packages/django/views/generic/base.py", line 104, in view
    return self.dispatch(request, *args, **kwargs)
  File "/root/medical_services/medicalenv/lib/python3.10/site-packages/rest_framework/views.py", line 511, in dispatch
    self.response = self.finalize_response(request, response, *args, **kwargs)
  File "/root/medical_services/medicalenv/lib/python3.10/site-packages/rest_framework/views.py", line 423, in finalize_response
    assert isinstance(response, HttpResponseBase), (
AssertionError: Expected a `Response`, `HttpResponse` or `HttpStreamingResponse` to be returned from the view, but received a `<class 'NoneType'>`
[2024-02-19 08:04:26] ERROR Internal Server Error: /api/v1/doctor/create_prescription/
Traceback (most recent call last):
  File "/root/medical_services/medicalenv/lib/python3.10/site-packages/django/core/handlers/exception.py", line 55, in inner
    response = get_response(request)
  File "/root/medical_services/medicalenv/lib/python3.10/site-packages/django/core/handlers/base.py", line 197, in _get_response
    response = wrapped_callback(request, *callback_args, **callback_kwargs)
  File "/root/medical_services/medicalenv/lib/python3.10/site-packages/django/views/decorators/csrf.py", line 56, in wrapper_view
    return view_func(*args, **kwargs)
  File "/root/medical_services/medicalenv/lib/python3.10/site-packages/django/views/generic/base.py", line 104, in view
    return self.dispatch(request, *args, **kwargs)
  File "/root/medical_services/medicalenv/lib/python3.10/site-packages/rest_framework/views.py", line 511, in dispatch
    self.response = self.finalize_response(request, response, *args, **kwargs)
  File "/root/medical_services/medicalenv/lib/python3.10/site-packages/rest_framework/views.py", line 423, in finalize_response
    assert isinstance(response, HttpResponseBase), (
AssertionError: Expected a `Response`, `HttpResponse` or `HttpStreamingResponse` to be returned from the view, but received a `<class 'NoneType'>`
[2024-02-19 08:04:31] ERROR Internal Server Error: /api/v1/doctor/create_prescription/
Traceback (most recent call last):
  File "/root/medical_services/medicalenv/lib/python3.10/site-packages/django/core/handlers/exception.py", line 55, in inner
    response = get_response(request)
  File "/root/medical_services/medicalenv/lib/python3.10/site-packages/django/core/handlers/base.py", line 197, in _get_response
    response = wrapped_callback(request, *callback_args, **callback_kwargs)
  File "/root/medical_services/medicalenv/lib/python3.10/site-packages/django/views/decorators/csrf.py", line 56, in wrapper_view
    return view_func(*args, **kwargs)
  File "/root/medical_services/medicalenv/lib/python3.10/site-packages/django/views/generic/base.py", line 104, in view
    return self.dispatch(request, *args, **kwargs)
  File "/root/medical_services/medicalenv/lib/python3.10/site-packages/rest_framework/views.py", line 511, in dispatch
    self.response = self.finalize_response(request, response, *args, **kwargs)
  File "/root/medical_services/medicalenv/lib/python3.10/site-packages/rest_framework/views.py", line 423, in finalize_response
    assert isinstance(response, HttpResponseBase), (
AssertionError: Expected a `Response`, `HttpResponse` or `HttpStreamingResponse` to be returned from the view, but received a `<class 'NoneType'>`
[2024-02-19 08:08:56] ERROR Internal Server Error: /api/v1/doctor/create_prescription/
Traceback (most recent call last):
  File "/root/medical_services/medicalenv/lib/python3.10/site-packages/django/core/handlers/exception.py", line 55, in inner
    response = get_response(request)
  File "/root/medical_services/medicalenv/lib/python3.10/site-packages/django/core/handlers/base.py", line 197, in _get_response
    response = wrapped_callback(request, *callback_args, **callback_kwargs)
  File "/root/medical_services/medicalenv/lib/python3.10/site-packages/django/views/decorators/csrf.py", line 56, in wrapper_view
    return view_func(*args, **kwargs)
  File "/root/medical_services/medicalenv/lib/python3.10/site-packages/django/views/generic/base.py", line 104, in view
    return self.dispatch(request, *args, **kwargs)
  File "/root/medical_services/medicalenv/lib/python3.10/site-packages/rest_framework/views.py", line 511, in dispatch
    self.response = self.finalize_response(request, response, *args, **kwargs)
  File "/root/medical_services/medicalenv/lib/python3.10/site-packages/rest_framework/views.py", line 423, in finalize_response
    assert isinstance(response, HttpResponseBase), (
AssertionError: Expected a `Response`, `HttpResponse` or `HttpStreamingResponse` to be returned from the view, but received a `<class 'NoneType'>`
[2024-02-19 08:10:35] ERROR Internal Server Error: /api/v1/doctor/create_prescription/
Traceback (most recent call last):
  File "/root/medical_services/medicalenv/lib/python3.10/site-packages/django/core/handlers/exception.py", line 55, in inner
    response = get_response(request)
  File "/root/medical_services/medicalenv/lib/python3.10/site-packages/django/core/handlers/base.py", line 197, in _get_response
    response = wrapped_callback(request, *callback_args, **callback_kwargs)
  File "/root/medical_services/medicalenv/lib/python3.10/site-packages/django/views/decorators/csrf.py", line 56, in wrapper_view
    return view_func(*args, **kwargs)
  File "/root/medical_services/medicalenv/lib/python3.10/site-packages/django/views/generic/base.py", line 104, in view
    return self.dispatch(request, *args, **kwargs)
  File "/root/medical_services/medicalenv/lib/python3.10/site-packages/rest_framework/views.py", line 511, in dispatch
    self.response = self.finalize_response(request, response, *args, **kwargs)
  File "/root/medical_services/medicalenv/lib/python3.10/site-packages/rest_framework/views.py", line 423, in finalize_response
    assert isinstance(response, HttpResponseBase), (
AssertionError: Expected a `Response`, `HttpResponse` or `HttpStreamingResponse` to be returned from the view, but received a `<class 'NoneType'>`
[2024-02-19 17:31:15] ERROR Internal Server Error: /api/v1/patient/create_appointment/
Traceback (most recent call last):
  File "/root/medical_services/medicalenv/lib/python3.10/site-packages/django/core/handlers/exception.py", line 55, in inner
    response = get_response(request)
  File "/root/medical_services/medicalenv/lib/python3.10/site-packages/django/core/handlers/base.py", line 197, in _get_response
    response = wrapped_callback(request, *callback_args, **callback_kwargs)
  File "/root/medical_services/medicalenv/lib/python3.10/site-packages/django/views/decorators/csrf.py", line 56, in wrapper_view
    return view_func(*args, **kwargs)
  File "/root/medical_services/medicalenv/lib/python3.10/site-packages/django/views/generic/base.py", line 104, in view
    return self.dispatch(request, *args, **kwargs)
  File "/root/medical_services/medicalenv/lib/python3.10/site-packages/rest_framework/views.py", line 511, in dispatch
    self.response = self.finalize_response(request, response, *args, **kwargs)
  File "/root/medical_services/medicalenv/lib/python3.10/site-packages/rest_framework/views.py", line 423, in finalize_response
    assert isinstance(response, HttpResponseBase), (
AssertionError: Expected a `Response`, `HttpResponse` or `HttpStreamingResponse` to be returned from the view, but received a `<class 'NoneType'>`
[2024-02-20 17:57:10] ERROR Internal Server Error: /api/v1/patient/create_appointment/
Traceback (most recent call last):
  File "/root/medical_services/medicalenv/lib/python3.10/site-packages/django/core/handlers/exception.py", line 55, in inner
    response = get_response(request)
  File "/root/medical_services/medicalenv/lib/python3.10/site-packages/django/core/handlers/base.py", line 197, in _get_response
    response = wrapped_callback(request, *callback_args, **callback_kwargs)
  File "/root/medical_services/medicalenv/lib/python3.10/site-packages/django/views/decorators/csrf.py", line 56, in wrapper_view
    return view_func(*args, **kwargs)
  File "/root/medical_services/medicalenv/lib/python3.10/site-packages/django/views/generic/base.py", line 104, in view
    return self.dispatch(request, *args, **kwargs)
  File "/root/medical_services/medicalenv/lib/python3.10/site-packages/rest_framework/views.py", line 511, in dispatch
    self.response = self.finalize_response(request, response, *args, **kwargs)
  File "/root/medical_services/medicalenv/lib/python3.10/site-packages/rest_framework/views.py", line 423, in finalize_response
    assert isinstance(response, HttpResponseBase), (
AssertionError: Expected a `Response`, `HttpResponse` or `HttpStreamingResponse` to be returned from the view, but received a `<class 'NoneType'>`
[2024-02-20 18:00:13] ERROR Internal Server Error: /api/v1/patient/create_appointment/
Traceback (most recent call last):
  File "/root/medical_services/medicalenv/lib/python3.10/site-packages/django/core/handlers/exception.py", line 55, in inner
    response = get_response(request)
  File "/root/medical_services/medicalenv/lib/python3.10/site-packages/django/core/handlers/base.py", line 197, in _get_response
    response = wrapped_callback(request, *callback_args, **callback_kwargs)
  File "/root/medical_services/medicalenv/lib/python3.10/site-packages/django/views/decorators/csrf.py", line 56, in wrapper_view
    return view_func(*args, **kwargs)
  File "/root/medical_services/medicalenv/lib/python3.10/site-packages/django/views/generic/base.py", line 104, in view
    return self.dispatch(request, *args, **kwargs)
  File "/root/medical_services/medicalenv/lib/python3.10/site-packages/rest_framework/views.py", line 511, in dispatch
    self.response = self.finalize_response(request, response, *args, **kwargs)
  File "/root/medical_services/medicalenv/lib/python3.10/site-packages/rest_framework/views.py", line 423, in finalize_response
    assert isinstance(response, HttpResponseBase), (
AssertionError: Expected a `Response`, `HttpResponse` or `HttpStreamingResponse` to be returned from the view, but received a `<class 'NoneType'>`
[2024-02-20 18:12:43] ERROR Internal Server Error: /api/v1/common/proceed_payment/
[2024-02-20 18:14:44] ERROR Internal Server Error: /api/v1/common/proceed_payment/
[2024-02-21 09:55:42] ERROR Internal Server Error: /api/v1/common/proceed_payment/
[2024-02-22 17:06:59] ERROR Internal Server Error: /api/v1/common/get_test/
[2024-02-22 17:06:59] ERROR Internal Server Error: /api/v1/common/get_test/
[2024-02-22 17:06:59] ERROR Internal Server Error: /api/v1/common/get_test/
[2024-02-22 17:06:59] ERROR Internal Server Error: /api/v1/common/get_test/
[2024-02-22 17:06:59] ERROR Internal Server Error: /api/v1/common/get_test/
[2024-02-22 17:07:00] ERROR Internal Server Error: /api/v1/common/get_test/
[2024-02-22 17:07:00] ERROR Internal Server Error: /api/v1/common/get_test/
[2024-02-22 17:07:00] ERROR Internal Server Error: /api/v1/common/get_test/
[2024-02-22 17:07:01] ERROR Internal Server Error: /api/v1/common/get_test/
[2024-02-22 17:07:01] ERROR Internal Server Error: /api/v1/common/get_test/
[2024-02-22 17:07:01] ERROR Internal Server Error: /api/v1/common/get_test/
[2024-02-22 17:07:02] ERROR Internal Server Error: /api/v1/common/get_test/
[2024-02-22 17:07:02] ERROR Internal Server Error: /api/v1/common/get_test/
[2024-02-22 17:07:02] ERROR Internal Server Error: /api/v1/common/get_test/
[2024-02-22 17:07:02] ERROR Internal Server Error: /api/v1/common/get_test/
[2024-02-22 17:07:06] ERROR Internal Server Error: /api/v1/common/get_test/
[2024-02-22 17:07:06] ERROR Internal Server Error: /api/v1/common/get_test/
[2024-02-22 17:07:06] ERROR Internal Server Error: /api/v1/common/get_test/
[2024-02-22 17:07:07] ERROR Internal Server Error: /api/v1/common/get_test/
[2024-02-22 17:07:12] ERROR Internal Server Error: /api/v1/common/get_test/
[2024-02-22 17:07:12] ERROR Internal Server Error: /api/v1/common/get_test/
[2024-02-22 17:07:35] ERROR Internal Server Error: /api/v1/common/get_test/
[2024-02-22 17:07:37] ERROR Internal Server Error: /api/v1/common/get_test/
[2024-02-22 17:07:39] ERROR Internal Server Error: /api/v1/common/get_test/
[2024-02-22 17:07:40] ERROR Internal Server Error: /api/v1/common/get_test/
[2024-02-22 17:07:40] ERROR Internal Server Error: /api/v1/common/get_test/
[2024-02-22 17:07:41] ERROR Internal Server Error: /api/v1/common/get_test/
[2024-02-22 17:07:41] ERROR Internal Server Error: /api/v1/common/get_test/
[2024-02-22 17:07:41] ERROR Internal Server Error: /api/v1/common/get_test/
[2024-02-22 17:07:41] ERROR Internal Server Error: /api/v1/common/get_test/
[2024-02-22 17:07:41] ERROR Internal Server Error: /api/v1/common/get_test/
[2024-02-22 17:07:42] ERROR Internal Server Error: /api/v1/common/get_test/
[2024-02-22 17:07:42] ERROR Internal Server Error: /api/v1/common/get_test/
[2024-02-22 17:07:43] ERROR Internal Server Error: /api/v1/common/get_test/
[2024-02-22 17:07:44] ERROR Internal Server Error: /api/v1/common/get_test/
[2024-02-22 17:07:44] ERROR Internal Server Error: /api/v1/common/get_test/
[2024-02-22 17:07:45] ERROR Internal Server Error: /api/v1/common/get_test/
[2024-02-22 17:07:45] ERROR Internal Server Error: /api/v1/common/get_test/
[2024-02-22 17:07:45] ERROR Internal Server Error: /api/v1/common/get_test/
[2024-02-22 17:07:46] ERROR Internal Server Error: /api/v1/common/get_test/
[2024-02-22 17:07:46] ERROR Internal Server Error: /api/v1/common/get_test/
[2024-02-22 17:07:47] ERROR Internal Server Error: /api/v1/common/get_test/
[2024-02-22 17:07:47] ERROR Internal Server Error: /api/v1/common/get_test/
[2024-02-22 17:07:47] ERROR Internal Server Error: /api/v1/common/get_test/
[2024-02-22 17:07:48] ERROR Internal Server Error: /api/v1/common/get_test/
[2024-02-22 17:07:48] ERROR Internal Server Error: /api/v1/common/get_test/
[2024-02-22 17:07:55] ERROR Internal Server Error: /api/v1/common/get_test/
[2024-02-22 17:08:22] ERROR Internal Server Error: /api/v1/common/get_test/
[2024-02-22 17:08:23] ERROR Internal Server Error: /api/v1/common/get_test/
[2024-02-22 17:08:24] ERROR Internal Server Error: /api/v1/common/get_test/
[2024-02-22 17:08:24] ERROR Internal Server Error: /api/v1/common/get_test/
[2024-02-22 17:08:24] ERROR Internal Server Error: /api/v1/common/get_test/
[2024-02-22 17:08:24] ERROR Internal Server Error: /api/v1/common/get_test/
[2024-02-22 17:08:25] ERROR Internal Server Error: /api/v1/common/get_test/
[2024-02-22 17:08:25] ERROR Internal Server Error: /api/v1/common/get_test/
[2024-02-22 17:08:27] ERROR Internal Server Error: /api/v1/common/get_test/
[2024-02-22 17:08:27] ERROR Internal Server Error: /api/v1/common/get_test/
[2024-02-22 17:08:27] ERROR Internal Server Error: /api/v1/common/get_test/
[2024-02-22 17:08:27] ERROR Internal Server Error: /api/v1/common/get_test/
[2024-02-22 17:08:28] ERROR Internal Server Error: /api/v1/common/get_test/
[2024-02-22 17:08:28] ERROR Internal Server Error: /api/v1/common/get_test/
[2024-02-22 17:08:28] ERROR Internal Server Error: /api/v1/common/get_test/
[2024-02-22 17:08:28] ERROR Internal Server Error: /api/v1/common/get_test/
[2024-02-22 17:08:28] ERROR Internal Server Error: /api/v1/common/get_test/
[2024-02-22 17:08:29] ERROR Internal Server Error: /api/v1/common/get_test/
[2024-02-22 17:08:29] ERROR Internal Server Error: /api/v1/common/get_test/
[2024-02-22 17:08:29] ERROR Internal Server Error: /api/v1/common/get_test/
[2024-02-22 17:09:31] ERROR Internal Server Error: /api/v1/common/get_test/
[2024-02-22 17:09:32] ERROR Internal Server Error: /api/v1/common/get_test/
[2024-02-22 17:09:32] ERROR Internal Server Error: /api/v1/common/get_test/
[2024-02-22 17:09:38] ERROR Internal Server Error: /api/v1/common/get_test/
[2024-02-22 17:09:39] ERROR Internal Server Error: /api/v1/common/get_test/
[2024-02-22 17:09:39] ERROR Internal Server Error: /api/v1/common/get_test/
[2024-02-22 17:09:40] ERROR Internal Server Error: /api/v1/common/get_test/
[2024-02-22 17:10:02] ERROR Internal Server Error: /api/v1/common/get_test/
[2024-02-24 17:39:09] ERROR Internal Server Error: /api/v1/common/payment_success/
[2024-02-26 10:33:17] ERROR Internal Server Error: /api/v1/common/payment_success/
[2024-02-26 11:04:44] ERROR Internal Server Error: /api/v1/common/payment_success/
[2024-02-26 11:08:23] ERROR Internal Server Error: /api/v1/common/payment_success/
[2024-02-26 11:16:04] ERROR Internal Server Error: /api/v1/common/payment_success/
[2024-02-26 11:38:05] ERROR Internal Server Error: /api/v1/common/payment_success/
[2024-02-26 13:01:33] ERROR Internal Server Error: /api/v1/common/payment_success/
[2024-02-26 13:16:10] ERROR Internal Server Error: /api/v1/common/payment_success/
[2024-02-26 13:22:35] ERROR Internal Server Error: /api/v1/common/payment_success/
[2024-02-26 19:45:07] ERROR Internal Server Error: /api/v1/common/payment_success/
[2024-02-26 20:03:49] ERROR Internal Server Error: /api/v1/common/payment_success/
[2024-02-26 20:12:10] ERROR Internal Server Error: /api/v1/common/payment_success/
[2024-02-27 18:05:27] ERROR Internal Server Error: /api/v1/common/payment_success/
[2024-02-27 18:12:39] ERROR Internal Server Error: /api/v1/common/payment_success/
[2024-02-28 15:44:32] ERROR Internal Server Error: /api/v1/common/proceed_payment/
[2024-02-28 15:44:53] ERROR Internal Server Error: /api/v1/common/proceed_payment/
[2024-02-28 15:44:57] ERROR Internal Server Error: /api/v1/common/proceed_payment/
[2024-02-28 15:46:43] ERROR Internal Server Error: /api/v1/common/proceed_payment/
[2024-02-28 15:47:00] ERROR Internal Server Error: /api/v1/common/proceed_payment/
[2024-02-28 15:52:07] ERROR Internal Server Error: /api/v1/common/proceed_payment/
[2024-02-28 15:58:37] ERROR Internal Server Error: /api/v1/common/proceed_payment/
[2024-02-28 16:25:16] ERROR Internal Server Error: /api/v1/common/proceed_payment/
[2024-02-29 02:35:53] ERROR Internal Server Error: /api/v1/common/payment_success/
[2024-02-29 02:37:10] ERROR Internal Server Error: /api/v1/common/payment_success/
[2024-02-29 15:53:58] ERROR Internal Server Error: /api/v1/common/payment_success/
[2024-02-29 15:58:21] ERROR Internal Server Error: /api/v1/common/payment_success/
[2024-02-29 16:38:07] ERROR Internal Server Error: /api/v1/common/payment_success/
[2024-03-05 15:50:58] ERROR Internal Server Error: /api/v1/common/proceed_payment/
[2024-03-10 11:46:39] ERROR Internal Server Error: /api/v1/common/payment_success/
[2024-03-10 11:49:30] ERROR Internal Server Error: /api/v1/common/payment_success/
[2024-03-10 11:53:17] ERROR Internal Server Error: /api/v1/common/payment_success/
[2024-03-10 11:58:42] ERROR Internal Server Error: /api/v1/common/payment_success/
[2024-04-29 13:10:11] ERROR Internal Server Error: /api/v1/common/get_test/
[2024-04-29 13:10:51] ERROR Internal Server Error: /api/v1/common/get_test/
[2024-12-08 10:18:01] ERROR Internal Server Error: /api/v1/common/proceed_payment/
[2024-12-08 10:18:58] ERROR Internal Server Error: /api/v1/common/proceed_payment/
[2024-12-08 10:21:49] ERROR Internal Server Error: /api/v1/common/proceed_payment/
[2025-01-30 18:07:26] ERROR Internal Server Error: /api/v1/patient/create_appointment/
Traceback (most recent call last):
  File "D:\medical_services\env\Lib\site-packages\django\core\handlers\exception.py", line 55, in inner
    response = get_response(request)
               ^^^^^^^^^^^^^^^^^^^^^
  File "D:\medical_services\env\Lib\site-packages\django\core\handlers\base.py", line 197, in _get_response
    response = wrapped_callback(request, *callback_args, **callback_kwargs)
               ^^^^^^^^^^^^^^^^^^^^^^^^^^^^^^^^^^^^^^^^^^^^^^^^^^^^^^^^^^^^
  File "D:\medical_services\env\Lib\site-packages\django\views\decorators\csrf.py", line 56, in wrapper_view
    return view_func(*args, **kwargs)
           ^^^^^^^^^^^^^^^^^^^^^^^^^^
  File "D:\medical_services\env\Lib\site-packages\django\views\generic\base.py", line 104, in view
    return self.dispatch(request, *args, **kwargs)
           ^^^^^^^^^^^^^^^^^^^^^^^^^^^^^^^^^^^^^^^
  File "D:\medical_services\env\Lib\site-packages\rest_framework\views.py", line 511, in dispatch
    self.response = self.finalize_response(request, response, *args, **kwargs)
                    ^^^^^^^^^^^^^^^^^^^^^^^^^^^^^^^^^^^^^^^^^^^^^^^^^^^^^^^^^^
  File "D:\medical_services\env\Lib\site-packages\rest_framework\views.py", line 423, in finalize_response
    assert isinstance(response, HttpResponseBase), (
           ^^^^^^^^^^^^^^^^^^^^^^^^^^^^^^^^^^^^^^
AssertionError: Expected a `Response`, `HttpResponse` or `HttpStreamingResponse` to be returned from the view, but received a `<class 'bool'>`
[2025-01-30 18:09:03] ERROR Internal Server Error: /api/v1/patient/create_appointment/
[2025-01-30 20:03:14] ERROR Internal Server Error: /api/v1/common/user_registration/
Traceback (most recent call last):
  File "D:\medical_services\env\Lib\site-packages\django\core\handlers\exception.py", line 55, in inner
    response = get_response(request)
               ^^^^^^^^^^^^^^^^^^^^^
  File "D:\medical_services\env\Lib\site-packages\django\core\handlers\base.py", line 197, in _get_response
    response = wrapped_callback(request, *callback_args, **callback_kwargs)
               ^^^^^^^^^^^^^^^^^^^^^^^^^^^^^^^^^^^^^^^^^^^^^^^^^^^^^^^^^^^^
  File "D:\medical_services\env\Lib\site-packages\django\views\decorators\csrf.py", line 56, in wrapper_view
    return view_func(*args, **kwargs)
           ^^^^^^^^^^^^^^^^^^^^^^^^^^
  File "D:\medical_services\env\Lib\site-packages\django\views\generic\base.py", line 104, in view
    return self.dispatch(request, *args, **kwargs)
           ^^^^^^^^^^^^^^^^^^^^^^^^^^^^^^^^^^^^^^^
  File "D:\medical_services\env\Lib\site-packages\rest_framework\views.py", line 509, in dispatch
    response = self.handle_exception(exc)
               ^^^^^^^^^^^^^^^^^^^^^^^^^^
  File "D:\medical_services\env\Lib\site-packages\rest_framework\views.py", line 469, in handle_exception
    self.raise_uncaught_exception(exc)
  File "D:\medical_services\env\Lib\site-packages\rest_framework\views.py", line 480, in raise_uncaught_exception
    raise exc
  File "D:\medical_services\env\Lib\site-packages\rest_framework\views.py", line 506, in dispatch
    response = handler(request, *args, **kwargs)
               ^^^^^^^^^^^^^^^^^^^^^^^^^^^^^^^^^
  File "D:\medical_services\healthcare\common\views.py", line 26, in post
    data =  requests.data
            ^^^^^^^^^^^^^
AttributeError: module 'requests' has no attribute 'data'
[2025-01-30 20:03:29] ERROR Internal Server Error: /api/v1/common/user_registration/
Traceback (most recent call last):
  File "D:\medical_services\env\Lib\site-packages\django\core\handlers\exception.py", line 55, in inner
    response = get_response(request)
               ^^^^^^^^^^^^^^^^^^^^^
  File "D:\medical_services\env\Lib\site-packages\django\core\handlers\base.py", line 197, in _get_response
    response = wrapped_callback(request, *callback_args, **callback_kwargs)
               ^^^^^^^^^^^^^^^^^^^^^^^^^^^^^^^^^^^^^^^^^^^^^^^^^^^^^^^^^^^^
  File "D:\medical_services\env\Lib\site-packages\django\views\decorators\csrf.py", line 56, in wrapper_view
    return view_func(*args, **kwargs)
           ^^^^^^^^^^^^^^^^^^^^^^^^^^
  File "D:\medical_services\env\Lib\site-packages\django\views\generic\base.py", line 104, in view
    return self.dispatch(request, *args, **kwargs)
           ^^^^^^^^^^^^^^^^^^^^^^^^^^^^^^^^^^^^^^^
  File "D:\medical_services\env\Lib\site-packages\rest_framework\views.py", line 509, in dispatch
    response = self.handle_exception(exc)
               ^^^^^^^^^^^^^^^^^^^^^^^^^^
  File "D:\medical_services\env\Lib\site-packages\rest_framework\views.py", line 469, in handle_exception
    self.raise_uncaught_exception(exc)
  File "D:\medical_services\env\Lib\site-packages\rest_framework\views.py", line 480, in raise_uncaught_exception
    raise exc
  File "D:\medical_services\env\Lib\site-packages\rest_framework\views.py", line 506, in dispatch
    response = handler(request, *args, **kwargs)
               ^^^^^^^^^^^^^^^^^^^^^^^^^^^^^^^^^
  File "D:\medical_services\healthcare\common\views.py", line 26, in post
    data =  requests.data
            ^^^^^^^^^^^^^
AttributeError: module 'requests' has no attribute 'data'
[2025-01-30 20:04:38] ERROR Internal Server Error: /api/v1/common/user_registration/
Traceback (most recent call last):
  File "D:\medical_services\env\Lib\site-packages\django\core\handlers\exception.py", line 55, in inner
    response = get_response(request)
               ^^^^^^^^^^^^^^^^^^^^^
  File "D:\medical_services\env\Lib\site-packages\django\core\handlers\base.py", line 197, in _get_response
    response = wrapped_callback(request, *callback_args, **callback_kwargs)
               ^^^^^^^^^^^^^^^^^^^^^^^^^^^^^^^^^^^^^^^^^^^^^^^^^^^^^^^^^^^^
  File "D:\medical_services\env\Lib\site-packages\django\views\decorators\csrf.py", line 56, in wrapper_view
    return view_func(*args, **kwargs)
           ^^^^^^^^^^^^^^^^^^^^^^^^^^
  File "D:\medical_services\env\Lib\site-packages\django\views\generic\base.py", line 104, in view
    return self.dispatch(request, *args, **kwargs)
           ^^^^^^^^^^^^^^^^^^^^^^^^^^^^^^^^^^^^^^^
  File "D:\medical_services\env\Lib\site-packages\rest_framework\views.py", line 509, in dispatch
    response = self.handle_exception(exc)
               ^^^^^^^^^^^^^^^^^^^^^^^^^^
  File "D:\medical_services\env\Lib\site-packages\rest_framework\views.py", line 469, in handle_exception
    self.raise_uncaught_exception(exc)
  File "D:\medical_services\env\Lib\site-packages\rest_framework\views.py", line 480, in raise_uncaught_exception
    raise exc
  File "D:\medical_services\env\Lib\site-packages\rest_framework\views.py", line 506, in dispatch
    response = handler(request, *args, **kwargs)
               ^^^^^^^^^^^^^^^^^^^^^^^^^^^^^^^^^
  File "D:\medical_services\healthcare\common\views.py", line 31, in post
    if serializer.is_valid():
       ^^^^^^^^^^^^^^^^^^^^^
  File "D:\medical_services\env\Lib\site-packages\rest_framework\serializers.py", line 227, in is_valid
    self._validated_data = self.run_validation(self.initial_data)
                           ^^^^^^^^^^^^^^^^^^^^^^^^^^^^^^^^^^^^^^
  File "D:\medical_services\env\Lib\site-packages\rest_framework\serializers.py", line 426, in run_validation
    value = self.to_internal_value(data)
            ^^^^^^^^^^^^^^^^^^^^^^^^^^^^
  File "D:\medical_services\env\Lib\site-packages\rest_framework\serializers.py", line 479, in to_internal_value
    for field in fields:
  File "D:\medical_services\env\Lib\site-packages\rest_framework\serializers.py", line 362, in _writable_fields
    for field in self.fields.values():
                 ^^^^^^^^^^^
  File "D:\medical_services\env\Lib\site-packages\django\utils\functional.py", line 57, in __get__
    res = instance.__dict__[self.name] = self.func(instance)
                                         ^^^^^^^^^^^^^^^^^^^
  File "D:\medical_services\env\Lib\site-packages\rest_framework\serializers.py", line 356, in fields
    for key, value in self.get_fields().items():
                      ^^^^^^^^^^^^^^^^^
  File "D:\medical_services\env\Lib\site-packages\rest_framework\serializers.py", line 1027, in get_fields
    assert hasattr(self, 'Meta'), (
           ^^^^^^^^^^^^^^^^^^^^^
AssertionError: Class MasterModelSerializers missing "Meta" attribute
[2025-01-30 20:05:47] ERROR Internal Server Error: /api/v1/common/user_registration/
Traceback (most recent call last):
  File "D:\medical_services\env\Lib\site-packages\django\core\handlers\exception.py", line 55, in inner
    response = get_response(request)
               ^^^^^^^^^^^^^^^^^^^^^
  File "D:\medical_services\env\Lib\site-packages\django\core\handlers\base.py", line 197, in _get_response
    response = wrapped_callback(request, *callback_args, **callback_kwargs)
               ^^^^^^^^^^^^^^^^^^^^^^^^^^^^^^^^^^^^^^^^^^^^^^^^^^^^^^^^^^^^
  File "D:\medical_services\env\Lib\site-packages\django\views\decorators\csrf.py", line 56, in wrapper_view
    return view_func(*args, **kwargs)
           ^^^^^^^^^^^^^^^^^^^^^^^^^^
  File "D:\medical_services\env\Lib\site-packages\django\views\generic\base.py", line 104, in view
    return self.dispatch(request, *args, **kwargs)
           ^^^^^^^^^^^^^^^^^^^^^^^^^^^^^^^^^^^^^^^
  File "D:\medical_services\env\Lib\site-packages\rest_framework\views.py", line 509, in dispatch
    response = self.handle_exception(exc)
               ^^^^^^^^^^^^^^^^^^^^^^^^^^
  File "D:\medical_services\env\Lib\site-packages\rest_framework\views.py", line 469, in handle_exception
    self.raise_uncaught_exception(exc)
  File "D:\medical_services\env\Lib\site-packages\rest_framework\views.py", line 480, in raise_uncaught_exception
    raise exc
  File "D:\medical_services\env\Lib\site-packages\rest_framework\views.py", line 506, in dispatch
    response = handler(request, *args, **kwargs)
               ^^^^^^^^^^^^^^^^^^^^^^^^^^^^^^^^^
  File "D:\medical_services\healthcare\common\views.py", line 33, in post
    if serializer.is_valid():
       ^^^^^^^^^^^^^^^^^^^^^
  File "D:\medical_services\env\Lib\site-packages\rest_framework\serializers.py", line 227, in is_valid
    self._validated_data = self.run_validation(self.initial_data)
                           ^^^^^^^^^^^^^^^^^^^^^^^^^^^^^^^^^^^^^^
  File "D:\medical_services\env\Lib\site-packages\rest_framework\serializers.py", line 426, in run_validation
    value = self.to_internal_value(data)
            ^^^^^^^^^^^^^^^^^^^^^^^^^^^^
  File "D:\medical_services\env\Lib\site-packages\rest_framework\serializers.py", line 479, in to_internal_value
    for field in fields:
  File "D:\medical_services\env\Lib\site-packages\rest_framework\serializers.py", line 362, in _writable_fields
    for field in self.fields.values():
                 ^^^^^^^^^^^
  File "D:\medical_services\env\Lib\site-packages\django\utils\functional.py", line 57, in __get__
    res = instance.__dict__[self.name] = self.func(instance)
                                         ^^^^^^^^^^^^^^^^^^^
  File "D:\medical_services\env\Lib\site-packages\rest_framework\serializers.py", line 356, in fields
    for key, value in self.get_fields().items():
                      ^^^^^^^^^^^^^^^^^
  File "D:\medical_services\env\Lib\site-packages\rest_framework\serializers.py", line 1027, in get_fields
    assert hasattr(self, 'Meta'), (
           ^^^^^^^^^^^^^^^^^^^^^
AssertionError: Class MasterModelSerializers missing "Meta" attribute
[2025-01-30 20:08:00] ERROR Internal Server Error: /api/v1/common/user_registration/
Traceback (most recent call last):
  File "D:\medical_services\env\Lib\site-packages\django\core\handlers\exception.py", line 55, in inner
    response = get_response(request)
               ^^^^^^^^^^^^^^^^^^^^^
  File "D:\medical_services\env\Lib\site-packages\django\core\handlers\base.py", line 197, in _get_response
    response = wrapped_callback(request, *callback_args, **callback_kwargs)
               ^^^^^^^^^^^^^^^^^^^^^^^^^^^^^^^^^^^^^^^^^^^^^^^^^^^^^^^^^^^^
  File "D:\medical_services\env\Lib\site-packages\django\views\decorators\csrf.py", line 56, in wrapper_view
    return view_func(*args, **kwargs)
           ^^^^^^^^^^^^^^^^^^^^^^^^^^
  File "D:\medical_services\env\Lib\site-packages\django\views\generic\base.py", line 104, in view
    return self.dispatch(request, *args, **kwargs)
           ^^^^^^^^^^^^^^^^^^^^^^^^^^^^^^^^^^^^^^^
  File "D:\medical_services\env\Lib\site-packages\rest_framework\views.py", line 509, in dispatch
    response = self.handle_exception(exc)
               ^^^^^^^^^^^^^^^^^^^^^^^^^^
  File "D:\medical_services\env\Lib\site-packages\rest_framework\views.py", line 469, in handle_exception
    self.raise_uncaught_exception(exc)
  File "D:\medical_services\env\Lib\site-packages\rest_framework\views.py", line 480, in raise_uncaught_exception
    raise exc
  File "D:\medical_services\env\Lib\site-packages\rest_framework\views.py", line 506, in dispatch
    response = handler(request, *args, **kwargs)
               ^^^^^^^^^^^^^^^^^^^^^^^^^^^^^^^^^
  File "D:\medical_services\healthcare\common\views.py", line 33, in post
    if serializer.is_valid():
       ^^^^^^^^^^^^^^^^^^^^^
  File "D:\medical_services\env\Lib\site-packages\rest_framework\serializers.py", line 227, in is_valid
    self._validated_data = self.run_validation(self.initial_data)
                           ^^^^^^^^^^^^^^^^^^^^^^^^^^^^^^^^^^^^^^
  File "D:\medical_services\env\Lib\site-packages\rest_framework\serializers.py", line 426, in run_validation
    value = self.to_internal_value(data)
            ^^^^^^^^^^^^^^^^^^^^^^^^^^^^
  File "D:\medical_services\env\Lib\site-packages\rest_framework\serializers.py", line 479, in to_internal_value
    for field in fields:
  File "D:\medical_services\env\Lib\site-packages\rest_framework\serializers.py", line 362, in _writable_fields
    for field in self.fields.values():
                 ^^^^^^^^^^^
  File "D:\medical_services\env\Lib\site-packages\django\utils\functional.py", line 57, in __get__
    res = instance.__dict__[self.name] = self.func(instance)
                                         ^^^^^^^^^^^^^^^^^^^
  File "D:\medical_services\env\Lib\site-packages\rest_framework\serializers.py", line 356, in fields
    for key, value in self.get_fields().items():
                      ^^^^^^^^^^^^^^^^^
  File "D:\medical_services\env\Lib\site-packages\rest_framework\serializers.py", line 1027, in get_fields
    assert hasattr(self, 'Meta'), (
           ^^^^^^^^^^^^^^^^^^^^^
AssertionError: Class MasterModelSerializers missing "Meta" attribute
[2025-01-31 13:10:00] ERROR Internal Server Error: /api/v1/common/user_registration/
Traceback (most recent call last):
  File "D:\medical_services\env\Lib\site-packages\django\core\handlers\exception.py", line 55, in inner
    response = get_response(request)
               ^^^^^^^^^^^^^^^^^^^^^
  File "D:\medical_services\env\Lib\site-packages\django\core\handlers\base.py", line 197, in _get_response
    response = wrapped_callback(request, *callback_args, **callback_kwargs)
               ^^^^^^^^^^^^^^^^^^^^^^^^^^^^^^^^^^^^^^^^^^^^^^^^^^^^^^^^^^^^
  File "D:\medical_services\env\Lib\site-packages\django\views\decorators\csrf.py", line 56, in wrapper_view
    return view_func(*args, **kwargs)
           ^^^^^^^^^^^^^^^^^^^^^^^^^^
  File "D:\medical_services\env\Lib\site-packages\django\views\generic\base.py", line 104, in view
    return self.dispatch(request, *args, **kwargs)
           ^^^^^^^^^^^^^^^^^^^^^^^^^^^^^^^^^^^^^^^
  File "D:\medical_services\env\Lib\site-packages\rest_framework\views.py", line 509, in dispatch
    response = self.handle_exception(exc)
               ^^^^^^^^^^^^^^^^^^^^^^^^^^
  File "D:\medical_services\env\Lib\site-packages\rest_framework\views.py", line 469, in handle_exception
    self.raise_uncaught_exception(exc)
  File "D:\medical_services\env\Lib\site-packages\rest_framework\views.py", line 480, in raise_uncaught_exception
    raise exc
  File "D:\medical_services\env\Lib\site-packages\rest_framework\views.py", line 506, in dispatch
    response = handler(request, *args, **kwargs)
               ^^^^^^^^^^^^^^^^^^^^^^^^^^^^^^^^^
  File "D:\medical_services\healthcare\common\views.py", line 33, in post
    if serializer.is_valid():
       ^^^^^^^^^^^^^^^^^^^^^
  File "D:\medical_services\env\Lib\site-packages\rest_framework\serializers.py", line 227, in is_valid
    self._validated_data = self.run_validation(self.initial_data)
                           ^^^^^^^^^^^^^^^^^^^^^^^^^^^^^^^^^^^^^^
  File "D:\medical_services\env\Lib\site-packages\rest_framework\serializers.py", line 426, in run_validation
    value = self.to_internal_value(data)
            ^^^^^^^^^^^^^^^^^^^^^^^^^^^^
  File "D:\medical_services\env\Lib\site-packages\rest_framework\serializers.py", line 479, in to_internal_value
    for field in fields:
  File "D:\medical_services\env\Lib\site-packages\rest_framework\serializers.py", line 362, in _writable_fields
    for field in self.fields.values():
                 ^^^^^^^^^^^
  File "D:\medical_services\env\Lib\site-packages\django\utils\functional.py", line 57, in __get__
    res = instance.__dict__[self.name] = self.func(instance)
                                         ^^^^^^^^^^^^^^^^^^^
  File "D:\medical_services\env\Lib\site-packages\rest_framework\serializers.py", line 356, in fields
    for key, value in self.get_fields().items():
                      ^^^^^^^^^^^^^^^^^
  File "D:\medical_services\env\Lib\site-packages\rest_framework\serializers.py", line 1027, in get_fields
    assert hasattr(self, 'Meta'), (
           ^^^^^^^^^^^^^^^^^^^^^
AssertionError: Class MasterModelSerializers missing "Meta" attribute
[2025-01-31 13:14:43] ERROR Internal Server Error: /api/v1/common/user_registration/
Traceback (most recent call last):
  File "D:\medical_services\env\Lib\site-packages\django\core\handlers\exception.py", line 55, in inner
    response = get_response(request)
               ^^^^^^^^^^^^^^^^^^^^^
  File "D:\medical_services\env\Lib\site-packages\django\core\handlers\base.py", line 197, in _get_response
    response = wrapped_callback(request, *callback_args, **callback_kwargs)
               ^^^^^^^^^^^^^^^^^^^^^^^^^^^^^^^^^^^^^^^^^^^^^^^^^^^^^^^^^^^^
  File "D:\medical_services\env\Lib\site-packages\django\views\decorators\csrf.py", line 56, in wrapper_view
    return view_func(*args, **kwargs)
           ^^^^^^^^^^^^^^^^^^^^^^^^^^
  File "D:\medical_services\env\Lib\site-packages\django\views\generic\base.py", line 104, in view
    return self.dispatch(request, *args, **kwargs)
           ^^^^^^^^^^^^^^^^^^^^^^^^^^^^^^^^^^^^^^^
  File "D:\medical_services\env\Lib\site-packages\rest_framework\views.py", line 509, in dispatch
    response = self.handle_exception(exc)
               ^^^^^^^^^^^^^^^^^^^^^^^^^^
  File "D:\medical_services\env\Lib\site-packages\rest_framework\views.py", line 469, in handle_exception
    self.raise_uncaught_exception(exc)
  File "D:\medical_services\env\Lib\site-packages\rest_framework\views.py", line 480, in raise_uncaught_exception
    raise exc
  File "D:\medical_services\env\Lib\site-packages\rest_framework\views.py", line 506, in dispatch
    response = handler(request, *args, **kwargs)
               ^^^^^^^^^^^^^^^^^^^^^^^^^^^^^^^^^
  File "D:\medical_services\healthcare\common\views.py", line 31, in post
    print("seri",serializer)
  File "D:\medical_services\env\Lib\site-packages\rest_framework\serializers.py", line 530, in __repr__
    return representation.serializer_repr(self, indent=1)
           ^^^^^^^^^^^^^^^^^^^^^^^^^^^^^^^^^^^^^^^^^^^^^^
  File "D:\medical_services\env\Lib\site-packages\rest_framework\utils\representation.py", line 77, in serializer_repr
    fields = serializer.fields
             ^^^^^^^^^^^^^^^^^
  File "D:\medical_services\env\Lib\site-packages\django\utils\functional.py", line 57, in __get__
    res = instance.__dict__[self.name] = self.func(instance)
                                         ^^^^^^^^^^^^^^^^^^^
  File "D:\medical_services\env\Lib\site-packages\rest_framework\serializers.py", line 356, in fields
    for key, value in self.get_fields().items():
                      ^^^^^^^^^^^^^^^^^
  File "D:\medical_services\env\Lib\site-packages\rest_framework\serializers.py", line 1027, in get_fields
    assert hasattr(self, 'Meta'), (
           ^^^^^^^^^^^^^^^^^^^^^
AssertionError: Class MasterModelSerializers missing "Meta" attribute
[2025-01-31 13:15:58] ERROR Internal Server Error: /api/v1/common/user_registration/
Traceback (most recent call last):
  File "D:\medical_services\env\Lib\site-packages\django\core\handlers\exception.py", line 55, in inner
    response = get_response(request)
               ^^^^^^^^^^^^^^^^^^^^^
  File "D:\medical_services\env\Lib\site-packages\django\core\handlers\base.py", line 197, in _get_response
    response = wrapped_callback(request, *callback_args, **callback_kwargs)
               ^^^^^^^^^^^^^^^^^^^^^^^^^^^^^^^^^^^^^^^^^^^^^^^^^^^^^^^^^^^^
  File "D:\medical_services\env\Lib\site-packages\django\views\decorators\csrf.py", line 56, in wrapper_view
    return view_func(*args, **kwargs)
           ^^^^^^^^^^^^^^^^^^^^^^^^^^
  File "D:\medical_services\env\Lib\site-packages\django\views\generic\base.py", line 104, in view
    return self.dispatch(request, *args, **kwargs)
           ^^^^^^^^^^^^^^^^^^^^^^^^^^^^^^^^^^^^^^^
  File "D:\medical_services\env\Lib\site-packages\rest_framework\views.py", line 509, in dispatch
    response = self.handle_exception(exc)
               ^^^^^^^^^^^^^^^^^^^^^^^^^^
  File "D:\medical_services\env\Lib\site-packages\rest_framework\views.py", line 469, in handle_exception
    self.raise_uncaught_exception(exc)
  File "D:\medical_services\env\Lib\site-packages\rest_framework\views.py", line 480, in raise_uncaught_exception
    raise exc
  File "D:\medical_services\env\Lib\site-packages\rest_framework\views.py", line 506, in dispatch
    response = handler(request, *args, **kwargs)
               ^^^^^^^^^^^^^^^^^^^^^^^^^^^^^^^^^
  File "D:\medical_services\healthcare\common\views.py", line 31, in post
    print("seri",serializer)
  File "D:\medical_services\env\Lib\site-packages\rest_framework\serializers.py", line 530, in __repr__
    return representation.serializer_repr(self, indent=1)
           ^^^^^^^^^^^^^^^^^^^^^^^^^^^^^^^^^^^^^^^^^^^^^^
  File "D:\medical_services\env\Lib\site-packages\rest_framework\utils\representation.py", line 77, in serializer_repr
    fields = serializer.fields
             ^^^^^^^^^^^^^^^^^
  File "D:\medical_services\env\Lib\site-packages\django\utils\functional.py", line 57, in __get__
    res = instance.__dict__[self.name] = self.func(instance)
                                         ^^^^^^^^^^^^^^^^^^^
  File "D:\medical_services\env\Lib\site-packages\rest_framework\serializers.py", line 356, in fields
    for key, value in self.get_fields().items():
                      ^^^^^^^^^^^^^^^^^
  File "D:\medical_services\env\Lib\site-packages\rest_framework\serializers.py", line 1027, in get_fields
    assert hasattr(self, 'Meta'), (
           ^^^^^^^^^^^^^^^^^^^^^
AssertionError: Class MasterModelSerializers missing "Meta" attribute
[2025-01-31 13:17:28] ERROR Internal Server Error: /api/v1/common/user_registration/
Traceback (most recent call last):
  File "D:\medical_services\env\Lib\site-packages\django\core\handlers\exception.py", line 55, in inner
    response = get_response(request)
               ^^^^^^^^^^^^^^^^^^^^^
  File "D:\medical_services\env\Lib\site-packages\django\core\handlers\base.py", line 197, in _get_response
    response = wrapped_callback(request, *callback_args, **callback_kwargs)
               ^^^^^^^^^^^^^^^^^^^^^^^^^^^^^^^^^^^^^^^^^^^^^^^^^^^^^^^^^^^^
  File "D:\medical_services\env\Lib\site-packages\django\views\decorators\csrf.py", line 56, in wrapper_view
    return view_func(*args, **kwargs)
           ^^^^^^^^^^^^^^^^^^^^^^^^^^
  File "D:\medical_services\env\Lib\site-packages\django\views\generic\base.py", line 104, in view
    return self.dispatch(request, *args, **kwargs)
           ^^^^^^^^^^^^^^^^^^^^^^^^^^^^^^^^^^^^^^^
  File "D:\medical_services\env\Lib\site-packages\rest_framework\views.py", line 509, in dispatch
    response = self.handle_exception(exc)
               ^^^^^^^^^^^^^^^^^^^^^^^^^^
  File "D:\medical_services\env\Lib\site-packages\rest_framework\views.py", line 469, in handle_exception
    self.raise_uncaught_exception(exc)
  File "D:\medical_services\env\Lib\site-packages\rest_framework\views.py", line 480, in raise_uncaught_exception
    raise exc
  File "D:\medical_services\env\Lib\site-packages\rest_framework\views.py", line 506, in dispatch
    response = handler(request, *args, **kwargs)
               ^^^^^^^^^^^^^^^^^^^^^^^^^^^^^^^^^
  File "D:\medical_services\healthcare\common\views.py", line 31, in post
    print("seri",serializer)
  File "D:\medical_services\env\Lib\site-packages\rest_framework\serializers.py", line 530, in __repr__
    return representation.serializer_repr(self, indent=1)
           ^^^^^^^^^^^^^^^^^^^^^^^^^^^^^^^^^^^^^^^^^^^^^^
  File "D:\medical_services\env\Lib\site-packages\rest_framework\utils\representation.py", line 77, in serializer_repr
    fields = serializer.fields
             ^^^^^^^^^^^^^^^^^
  File "D:\medical_services\env\Lib\site-packages\django\utils\functional.py", line 57, in __get__
    res = instance.__dict__[self.name] = self.func(instance)
                                         ^^^^^^^^^^^^^^^^^^^
  File "D:\medical_services\env\Lib\site-packages\rest_framework\serializers.py", line 356, in fields
    for key, value in self.get_fields().items():
                      ^^^^^^^^^^^^^^^^^
  File "D:\medical_services\env\Lib\site-packages\rest_framework\serializers.py", line 1027, in get_fields
    assert hasattr(self, 'Meta'), (
           ^^^^^^^^^^^^^^^^^^^^^
AssertionError: Class MasterModelSerializers missing "Meta" attribute
[2025-01-31 13:18:31] ERROR Internal Server Error: /api/v1/common/user_registration/
[2025-01-31 13:19:34] ERROR Internal Server Error: /api/v1/common/user_registration/
[2025-01-31 13:20:33] ERROR Internal Server Error: /api/v1/common/user_registration/
[2025-01-31 16:28:13] ERROR Internal Server Error: /api/v1/common/user_registration/
[2025-01-31 16:36:01] ERROR Internal Server Error: /api/v1/common/user_registration/
[2025-01-31 16:42:18] ERROR Internal Server Error: /api/v1/common/user_registration/
[2025-01-31 16:46:26] ERROR Internal Server Error: /api/v1/common/user_registration/
[2025-01-31 16:53:35] ERROR Internal Server Error: /api/v1/common/user_registration/
[2025-01-31 16:56:10] ERROR Internal Server Error: /api/v1/common/user_registration/
[2025-01-31 16:58:50] ERROR Internal Server Error: /api/v1/common/user_registration/
[2025-02-03 12:24:18] ERROR Internal Server Error: /api/v1/common/user_registration/
